Workbook

Sheet Sheet1
A1: ID | B1: 课程名称 | C1: 上课时间（北京） | D1: 上课时间（沙特） | E1: 预约类型 | F1: 课程类型 | G1: 老师名称 | H1: 老师id | I1: 学生名称 | J1: 学生id | K1: 51talk预约id | L1: merithubId | M1: 课程状态 | N1: 预约上课教材 | O1: 实际上课教材 | P1: 约课时间 | Q1: 销售ID | R1: 上课时长 | S1: 是否成交 | T1: CC
A2: 4031 | B2: student-- | C2: 2026-04-25 20:30 ~ 21:00 | D2: 2026-04-25 15:30 ~ 16:00 | E2: 自约 | F2: free | H2: 0 | I2: student | J2: 62996274 | K2: 528766839 | L2: d7kijn4rtl0pvidbb720 | M2: on | N2: related to exams you are facing now-phonetic | P2: 2026-04-23 04:04:39 | Q2: 4123060 | S2: free | T2: =VLOOKUP(Q2,Sheet2!A:C,3,FALSE) -> EGCC-maiwaheed
A3: 4028 | B3: student-related to exams you are facing now-Vocabulary skills - | C3: 2026-04-25 18:30 ~ 19:00 | D3: 2026-04-25 13:30 ~ 14:00 | E3: 自约 | F3: free | H3: 0 | I3: student | J3: 62739656 | K3: 528741930 | L3: d7kh1ccrtl0pvidb4tm0 | M3: on | N3: related to exams you are facing now-Vocabulary skills | P3: 2026-04-23 02:17:16 | Q3: 4115904 | S3: free | T3: =VLOOKUP(Q3,Sheet2!A:C,3,FALSE) -> #N/A
A4: 4024 | B4: student-- | C4: 2026-04-25 18:00 ~ 18:30 | D4: 2026-04-25 13:00 ~ 13:30 | E4: 自约 | F4: free | H4: 0 | I4: student | J4: 62995634 | K4: 528739889 | L4: d7kg5osrtl0pvidav3g0 | M4: on | N4: related to exams you are facing now-phonetic | P4: 2026-04-23 01:18:22 | Q4: 4124168 | S4: free | T4: =VLOOKUP(Q4,Sheet2!A:C,3,FALSE) -> 51hassan02
A5: 3923 | B5: student-related to exams you are facing now-Reading exam skills - | C5: 2026-04-24 02:30 ~ 03:00 | D5: 2026-04-23 21:30 ~ 22:00 | E5: 自约 | F5: free | H5: 0 | I5: student | J5: 62980864 | K5: 528498587 | L5: d7jd8pcrtl0s0eknqqfg | M5: on | N5: related to exams you are facing now-Reading exam skills | P5: 2026-04-21 09:35:27 | Q5: 4122734 | S5: free | T5: =VLOOKUP(Q5,Sheet2!A:C,3,FALSE) -> EGCC-eman.amr
A6: 3924 | B6: student-culture and interests-A day of yours- | C6: 2026-04-24 02:30 ~ 03:00 | D6: 2026-04-23 21:30 ~ 22:00 | E6: 自约 | F6: free | H6: 0 | I6: student | J6: 62981167 | K6: 528501566 | L6: d7jefp4rtl0s0eknsha0 | M6: cancel | N6: culture and interests-A day of yours | P6: 2026-04-21 10:58:39 | Q6: 4123060 | S6: free | T6: =VLOOKUP(Q6,Sheet2!A:C,3,FALSE) -> EGCC-maiwaheed
A7: 3961 | B7: student--Habiba Muhammed | C7: 2026-04-24 02:30 ~ 03:00 | D7: 2026-04-23 21:30 ~ 22:00 | E7: 自约 | F7: free | H7: 0 | I7: student | J7: 62987542 | K7: 528586236 | L7: d7jqjekrtl0pvid746jg | M7: on | P7: 2026-04-22 00:45:41 | Q7: 4121806 | S7: free | T7: =VLOOKUP(Q7,Sheet2!A:C,3,FALSE) -> 51habiba.hassan
A8: 4034 | B8: student--Fatma Mohamed | C8: 2026-04-24 02:30 ~ 03:00 | D8: 2026-04-23 21:30 ~ 22:00 | E8: 自约 | F8: free | H8: 0 | I8: student | J8: 62996522 | K8: 528780854 | L8: d7kk094rtl0pvidbf1ug | M8: on | N8: related to exams you are facing now-phonetic | P8: 2026-04-23 05:39:42 | Q8: 4123061 | S8: free | T8: =VLOOKUP(Q8,Sheet2!A:C,3,FALSE) -> EGCC-fatmamohamed
A9: 3951 | B9: student-culture and interests-A day of yours- | C9: 2026-04-24 01:30 ~ 02:00 | D9: 2026-04-23 20:30 ~ 21:00 | E9: 自约 | F9: free | H9: 0 | I9: student | J9: 62985541 | K9: 528557732 | L9: d7jnf4crtl0pvid63cjg | M9: on | N9: culture and interests-A day of yours | P9: 2026-04-21 21:11:40 | Q9: 4121807 | S9: free | T9: =VLOOKUP(Q9,Sheet2!A:C,3,FALSE) -> 51nadamuhammad
A10: 3966 | B10: student-culture and interests-A day of yours- | C10: 2026-04-24 01:30 ~ 02:00 | D10: 2026-04-23 20:30 ~ 21:00 | E10: 自约 | F10: free | H10: 0 | I10: student | J10: 62987400 | K10: 528590349 | L10: d7jr6vcrtl0pvid7b7dg | M10: on | N10: culture and interests-A day of yours | P10: 2026-04-22 01:27:20 | Q10: 4123061 | S10: free | T10: =VLOOKUP(Q10,Sheet2!A:C,3,FALSE) -> EGCC-fatmamohamed
A11: 3986 | B11: student-related to exams you are facing now-phonetic- | C11: 2026-04-24 01:30 ~ 02:00 | D11: 2026-04-23 20:30 ~ 21:00 | E11: 自约 | F11: free | H11: 0 | I11: student | J11: 62988786 | K11: 528645963 | L11: d7k1vikrtl0pvid872q0 | M11: on | N11: related to exams you are facing now-phonetic | P11: 2026-04-22 09:09:25 | Q11: 4122734 | S11: free | T11: =VLOOKUP(Q11,Sheet2!A:C,3,FALSE) -> EGCC-eman.amr
A12: 3950 | B12: student--Hassan Ahmed | C12: 2026-04-24 01:00 ~ 01:30 | D12: 2026-04-23 20:00 ~ 20:30 | E12: 自约 | F12: free | H12: 0 | I12: student | J12: 62985725 | K12: 528557540 | L12: d7jndbkrtl0pvid633d0 | M12: cancel | P12: 2026-04-21 21:07:53 | Q12: 4124168 | S12: free | T12: =VLOOKUP(Q12,Sheet2!A:C,3,FALSE) -> 51hassan02
A13: 4004 | B13: student-related to exams you are facing now-phonetic-Fatma Mohamed | C13: 2026-04-24 01:00 ~ 01:30 | D13: 2026-04-23 20:00 ~ 20:30 | E13: 代约 | F13: free | H13: 0 | I13: student | J13: 62946072 | K13: 528700025 | L13: d7kbmosrtl0pvid9m15g | M13: on | N13: related to exams you are facing now-phonetic | P13: 2026-04-22 20:13:17 | Q13: 4123061 | S13: free | T13: =VLOOKUP(Q13,Sheet2!A:C,3,FALSE) -> EGCC-fatmamohamed
A14: 4011 | B14: student--Nada Mohamed | C14: 2026-04-24 01:00 ~ 01:30 | D14: 2026-04-23 20:00 ~ 20:30 | E14: 自约 | F14: free | H14: 0 | I14: student | J14: 62993847 | K14: 528706635 | L14: d7kci6krtl0pvid9t970 | M14: on | N14: related to exams you are facing now-phonetic | P14: 2026-04-22 21:11:49 | Q14: 4121807 | S14: free | T14: =VLOOKUP(Q14,Sheet2!A:C,3,FALSE) -> 51nadamuhammad
A15: 3960 | B15: student--Fatma Mohamed | C15: 2026-04-24 00:30 ~ 01:00 | D15: 2026-04-23 19:30 ~ 20:00 | E15: 自约 | F15: free | H15: 0 | I15: student | J15: 62987319 | K15: 528575856 | L15: d7jq94krtl0pvid719o0 | M15: on | P15: 2026-04-22 00:23:39 | Q15: 4123061 | S15: free | T15: =VLOOKUP(Q15,Sheet2!A:C,3,FALSE) -> EGCC-fatmamohamed
A16: 4029 | B16: student--Mahmoud Badawy | C16: 2026-04-24 00:30 ~ 01:00 | D16: 2026-04-23 19:30 ~ 20:00 | E16: 自约 | F16: free | H16: 0 | I16: student | J16: 62995974 | K16: 528742726 | L16: d7khibsrtl0pvidb78ag | M16: cancel | N16: related to exams you are facing now-phonetic | P16: 2026-04-23 02:53:30 | Q16: 4123056 | S16: free | T16: =VLOOKUP(Q16,Sheet2!A:C,3,FALSE) -> EGCC-mahmoudbadawy
A17: 3979 | B17: student-related to exams you are facing now-Vocabulary skills - | C17: 2026-04-24 00:00 ~ 00:30 | D17: 2026-04-23 19:00 ~ 19:30 | E17: 自约 | F17: free | H17: 0 | I17: student | J17: 62988316 | K17: 528600448 | L17: d7jstt4rtl0pvid7lig0 | M17: cancel | N17: related to exams you are facing now-Vocabulary skills | P17: 2026-04-22 03:24:30 | Q17: 4123057 | S17: free | T17: =VLOOKUP(Q17,Sheet2!A:C,3,FALSE) -> EGCC-tasneemmahmoud
A18: 3984 | B18: student-related to exams you are facing now-Vocabulary skills - | C18: 2026-04-24 00:00 ~ 00:30 | D18: 2026-04-23 19:00 ~ 19:30 | E18: 自约 | F18: free | H18: 0 | I18: student | J18: 62988612 | K18: 528641980 | L18: d7jv7ckrtl0pvid7rk1g | M18: on | N18: related to exams you are facing now-Vocabulary skills | P18: 2026-04-22 06:01:16 | Q18: 4123061 | S18: free | T18: =VLOOKUP(Q18,Sheet2!A:C,3,FALSE) -> EGCC-fatmamohamed
A19: 4001 | B19: student-culture and interests-A day of yours-user409842 | C19: 2026-04-24 00:00 ~ 00:30 | D19: 2026-04-23 19:00 ~ 19:30 | E19: 代约 | F19: free | H19: 0 | I19: student | J19: 62949507 | K19: 528689140 | L19: d7kaitkrtl0pvid9e4ug | M19: cancel | N19: culture and interests-A day of yours | P19: 2026-04-22 18:56:48 | Q19: 4123057 | S19: free | T19: =VLOOKUP(Q19,Sheet2!A:C,3,FALSE) -> EGCC-tasneemmahmoud
A20: 4013 | B20: student-- | C20: 2026-04-24 00:00 ~ 00:30 | D20: 2026-04-23 19:00 ~ 19:30 | E20: 自约 | F20: free | H20: 0 | I20: student | J20: 62994205 | K20: 528706481 | L20: d7kcj04rtl0pvid9tdv0 | M20: on | N20: related to exams you are facing now-phonetic | P20: 2026-04-22 21:13:31 | Q20: 4123056 | S20: free | T20: =VLOOKUP(Q20,Sheet2!A:C,3,FALSE) -> EGCC-mahmoudbadawy
A21: 3987 | B21: student-- | C21: 2026-04-23 23:30 ~ 00:00 | D21: 2026-04-23 18:30 ~ 19:00 | E21: 自约 | F21: free | H21: 0 | I21: student | J21: 62989129 | K21: 528646597 | L21: d7k2ebsrtl0pvid88ba0 | M21: on | P21: 2026-04-22 09:40:58 | Q21: 4123057 | S21: free | T21: =VLOOKUP(Q21,Sheet2!A:C,3,FALSE) -> EGCC-tasneemmahmoud
A22: 3992 | B22: student-- | C22: 2026-04-23 23:30 ~ 00:00 | D22: 2026-04-23 18:30 ~ 19:00 | E22: 自约 | F22: free | H22: 0 | I22: student | J22: 62990418 | K22: 528658218 | L22: d7k5ckkrtl0pvid8g870 | M22: cancel | N22: related to exams you are facing now-phonetic | P22: 2026-04-22 13:02:05 | Q22: 4121806 | S22: free | T22: =VLOOKUP(Q22,Sheet2!A:C,3,FALSE) -> 51habiba.hassan
A23: 4002 | B23: student-culture and interests-A day of yours-Mai Waheed | C23: 2026-04-23 23:00 ~ 23:30 | D23: 2026-04-23 18:00 ~ 18:30 | E23: 代约 | F23: free | H23: 0 | I23: student | J23: 62991976 | K23: 528690078 | L23: d7kamc4rtl0pvid9f7sg | M23: on | N23: culture and interests-A day of yours | P23: 2026-04-22 19:04:10 | Q23: 4123060 | S23: free | T23: =VLOOKUP(Q23,Sheet2!A:C,3,FALSE) -> EGCC-maiwaheed
A24: 4007 | B24: student-culture and interests-A day of yours-Fatma Mohamed | C24: 2026-04-23 23:00 ~ 23:30 | D24: 2026-04-23 18:00 ~ 18:30 | E24: 代约 | F24: free | H24: 0 | I24: student | J24: 62959478 | K24: 528703462 | L24: d7kc4f4rtl0pvid9prvg | M24: on | N24: culture and interests-A day of yours | P24: 2026-04-22 20:42:31 | Q24: 4123061 | S24: free | T24: =VLOOKUP(Q24,Sheet2!A:C,3,FALSE) -> EGCC-fatmamohamed
A25: 3990 | B25: student--Fatma Mohamed | C25: 2026-04-23 22:00 ~ 22:30 | D25: 2026-04-23 17:00 ~ 17:30 | E25: 自约 | F25: free | H25: 0 | I25: student | J25: 62990121 | K25: 528655413 | L25: d7k4pkcrtl0pvid8eb2g | M25: on | N25: related to exams you are facing now-phonetic | P25: 2026-04-22 12:21:31 | Q25: 4123061 | S25: free | T25: =VLOOKUP(Q25,Sheet2!A:C,3,FALSE) -> EGCC-fatmamohamed
A26: 3998 | B26: student--Mai Waheed | C26: 2026-04-23 22:00 ~ 22:30 | D26: 2026-04-23 17:00 ~ 17:30 | E26: 自约 | F26: free | H26: 0 | I26: student | J26: 62991976 | K26: 528680953 | L26: d7k9nrkrtl0pvid97pf0 | M26: cancel | N26: related to exams you are facing now-phonetic | P26: 2026-04-22 17:59:05 | Q26: 4123060 | S26: free | T26: =VLOOKUP(Q26,Sheet2!A:C,3,FALSE) -> EGCC-maiwaheed
A27: 3931 | B27: student-- | C27: 2026-04-23 21:30 ~ 22:00 | D27: 2026-04-23 16:30 ~ 17:00 | E27: 自约 | F27: free | H27: 0 | I27: student | J27: 62982206 | K27: 528511327 | L27: d7jghi4rtl0s0eko0560 | M27: on | P27: 2026-04-21 13:18:59 | Q27: 4122734 | S27: free | T27: =VLOOKUP(Q27,Sheet2!A:C,3,FALSE) -> EGCC-eman.amr
A28: 4026 | B28: student-culture and interests-A day of yours-Habiba Muhammed | C28: 2026-04-23 21:30 ~ 22:00 | D28: 2026-04-23 16:30 ~ 17:00 | E28: 代约 | F28: free | H28: 0 | I28: student | J28: 62995856 | K28: 528741075 | L28: d7kgkicrtl0pvidb1pp0 | M28: on | N28: culture and interests-A day of yours | P28: 2026-04-23 01:49:55 | Q28: 4121806 | S28: free | T28: =VLOOKUP(Q28,Sheet2!A:C,3,FALSE) -> 51habiba.hassan
A29: 4027 | B29: Yousef-related to exams you are facing now-Vocabulary skills - | C29: 2026-04-23 21:00 ~ 21:30 | D29: 2026-04-23 16:00 ~ 16:30 | E29: 自约 | F29: free | H29: 0 | I29: Yousef | J29: 62879304 | K29: 528741650 | L29: d7kgv9krtl0pvidb4jhg | M29: on | N29: related to exams you are facing now-Vocabulary skills | P29: 2026-04-23 02:12:49 | Q29: 4119745 | S29: free | T29: =VLOOKUP(Q29,Sheet2!A:C,3,FALSE) -> #N/A
A30: 3997 | B30: student--user409842 | C30: 2026-04-23 20:30 ~ 21:00 | D30: 2026-04-23 15:30 ~ 16:00 | E30: 自约 | F30: free | H30: 0 | I30: student | J30: 62992058 | K30: 528680837 | L30: d7k9mr4rtl0pvid97e10 | M30: on | N30: related to exams you are facing now-phonetic | P30: 2026-04-22 17:56:55 | Q30: 4123057 | S30: free | T30: =VLOOKUP(Q30,Sheet2!A:C,3,FALSE) -> EGCC-tasneemmahmoud
A31: 3999 | B31: student-culture and interests-A day of yours-user409842 | C31: 2026-04-23 20:30 ~ 21:00 | D31: 2026-04-23 15:30 ~ 16:00 | E31: 代约 | F31: free | H31: 0 | I31: student | J31: 62992183 | K31: 528685077 | L31: d7ka664rtl0pvid9b4lg | M31: on | N31: culture and interests-A day of yours | P31: 2026-04-22 18:29:39 | Q31: 4123057 | S31: free | T31: =VLOOKUP(Q31,Sheet2!A:C,3,FALSE) -> EGCC-tasneemmahmoud
A32: 3938 | B32: student-related to exams you are facing now-Vocabulary skills - | C32: 2026-04-23 20:00 ~ 20:30 | D32: 2026-04-23 15:00 ~ 15:30 | E32: 自约 | F32: free | H32: 0 | I32: student | J32: 62984086 | K32: 528535893 | L32: d7jl4c4rtl0t9uck6vv0 | M32: on | N32: related to exams you are facing now-Vocabulary skills | P32: 2026-04-21 18:32:11 | Q32: 4123061 | S32: free | T32: =VLOOKUP(Q32,Sheet2!A:C,3,FALSE) -> EGCC-fatmamohamed
A33: 3988 | B33: student--Mai Waheed | C33: 2026-04-23 20:00 ~ 20:30 | D33: 2026-04-23 15:00 ~ 15:30 | E33: 自约 | F33: free | H33: 0 | I33: student | J33: 62989518 | K33: 528649722 | L33: d7k3bt4rtl0pvid8a470 | M33: on | P33: 2026-04-22 10:43:59 | Q33: 4123060 | S33: free | T33: =VLOOKUP(Q33,Sheet2!A:C,3,FALSE) -> EGCC-maiwaheed
A34: 4023 | B34: student-culture and interests-A day of yours- | C34: 2026-04-23 20:00 ~ 20:30 | D34: 2026-04-23 15:00 ~ 15:30 | E34: 自约 | F34: free | H34: 0 | I34: student | J34: 61023454 | K34: 528732618 | L34: d7kffj4rtl0pvidaot2g | M34: on | N34: culture and interests-A day of yours | P34: 2026-04-23 00:31:03 | Q34: 4119324 | S34: free | T34: =VLOOKUP(Q34,Sheet2!A:C,3,FALSE) -> #N/A
A35: 4030 | B35: student-culture and interests-A day of yours- | C35: 2026-04-23 20:00 ~ 20:30 | D35: 2026-04-23 15:00 ~ 15:30 | E35: 自约 | F35: free | H35: 0 | I35: student | J35: 62996037 | K35: 528743053 | L35: d7khqekrtl0pvidb8qbg | M35: on | N35: culture and interests-A day of yours | P35: 2026-04-23 03:10:45 | Q35: 4123057 | S35: free | T35: =VLOOKUP(Q35,Sheet2!A:C,3,FALSE) -> EGCC-tasneemmahmoud
A36: 4033 | B36: student-- | C36: 2026-04-23 20:00 ~ 20:30 | D36: 2026-04-23 15:00 ~ 15:30 | E36: 自约 | F36: free | H36: 0 | I36: student | J36: 59512554 | K36: 528780592 | L36: d7kjnscrtl0pvidbeaqg | M36: on | N36: related to exams you are facing now-phonetic | P36: 2026-04-23 05:21:47 | Q36: 4117678 | S36: free | T36: =VLOOKUP(Q36,Sheet2!A:C,3,FALSE) -> #N/A
A37: 3985 | B37: student-related to exams you are facing now-Vocabulary skills - | C37: 2026-04-23 19:30 ~ 20:00 | D37: 2026-04-23 14:30 ~ 15:00 | E37: 自约 | F37: free | H37: 0 | I37: student | J37: 62988574 | K37: 528643563 | L37: d7k0p9crtl0pvid81rp0 | M37: cancel | N37: related to exams you are facing now-Vocabulary skills | P37: 2026-04-22 07:47:43 | Q37: 4121806 | S37: free | T37: =VLOOKUP(Q37,Sheet2!A:C,3,FALSE) -> 51habiba.hassan
A38: 4018 | B38: student--Mai Waheed | C38: 2026-04-23 19:30 ~ 20:00 | D38: 2026-04-23 14:30 ~ 15:00 | E38: 自约 | F38: free | H38: 0 | I38: student | J38: 62994199 | K38: 528713534 | L38: d7kdbfkrtl0pvida5o3g | M38: on | N38: related to exams you are facing now-phonetic | P38: 2026-04-22 22:05:44 | Q38: 4123060 | S38: free | T38: =VLOOKUP(Q38,Sheet2!A:C,3,FALSE) -> EGCC-maiwaheed
A39: 3928 | B39: student-related to exams you are facing now-phonetic- | C39: 2026-04-23 18:30 ~ 19:00 | D39: 2026-04-23 13:30 ~ 14:00 | E39: 自约 | F39: free | H39: 0 | I39: student | J39: 62981841 | K39: 528509512 | L39: d7jg47crtl0s0eknv560 | M39: on | N39: related to exams you are facing now-phonetic | P39: 2026-04-21 12:50:32 | Q39: 4123060 | S39: free | T39: =VLOOKUP(Q39,Sheet2!A:C,3,FALSE) -> EGCC-maiwaheed
A40: 3921 | B40: student-related to exams you are facing now-Vocabulary skills - | C40: 2026-04-23 18:00 ~ 18:30 | D40: 2026-04-23 13:00 ~ 13:30 | E40: 自约 | F40: free | H40: 0 | I40: student | J40: 62981011 | K40: 528497172 | L40: d7jcgokrtl0s0eknogp0 | M40: on | N40: related to exams you are facing now-Vocabulary skills | P40: 2026-04-21 08:44:12 | Q40: 4123061 | S40: free | T40: =VLOOKUP(Q40,Sheet2!A:C,3,FALSE) -> EGCC-fatmamohamed
...

Sheet Sheet2
A1: sales_id | B1: sales_group | C1: sales_name
A2: 4121806 | B2: 001 | C2: 51habiba.hassan
A3: 4122734 | B3: 001 | C3: EGCC-eman.amr
A4: 4123059 | B4: 001 | C4: EGCC-nadahassan
A5: 4121807 | B5: 002 | C5: 51nadamuhammad
A6: 4123057 | B6: 002 | C6: EGCC-tasneemmahmoud
A7: 4123060 | B7: 002 | C7: EGCC-maiwaheed
A8: 4123061 | B8: 002 | C8: EGCC-fatmamohamed
A9: 4124168 | B9: 001 | C9: 51hassan02
A10: 4123056 | B10: 002 | C10: EGCC-mahmoudbadawy
